//
//  Task+InstrumentsTestCase.swift
//
//  Copyright Â© 2022 Aleksei Zaikin.
//
//  Permission is hereby granted, free of charge, to any person obtaining a copy
//  of this software and associated documentation files (the "Software"), to deal
//  in the Software without restriction, including without limitation the rights
//  to use, copy, modify, merge, publish, distribute, sublicense, and/or sell
//  copies of the Software, and to permit persons to whom the Software is
//  furnished to do so, subject to the following conditions:
//
//  The above copyright notice and this permission notice shall be included in
//  all copies or substantial portions of the Software.
//
//  THE SOFTWARE IS PROVIDED "AS IS", WITHOUT WARRANTY OF ANY KIND, EXPRESS OR
//  IMPLIED, INCLUDING BUT NOT LIMITED TO THE WARRANTIES OF MERCHANTABILITY,
//  FITNESS FOR A PARTICULAR PURPOSE AND NON-INFRINGEMENT. IN NO EVENT SHALL THE
//  AUTHORS OR COPYRIGHT HOLDERS BE LIABLE FOR ANY CLAIM, DAMAGES OR OTHER
//  LIABILITY, WHETHER IN AN ACTION OF CONTRACT, TORT OR OTHERWISE, ARISING FROM,
//  OUT OF OR IN CONNECTION WITH THE SOFTWARE OR THE USE OR OTHER DEALINGS IN
//  THE SOFTWARE.
//

import Instruments
import XCTest

class TaskInstrumentsTestCase: XCTestCase {
   func test_task_retriesOperationUntilSuccess() async throws {
      let service = Service(throwsError: false)
      let task = Task.retrying {
         try await service.operation()
      }
      let int = try await task.value
      XCTAssertEqual(int, 42)
   }

   func test_task_throwsError_ifRetriesCountExceeded() async {
      let service = Service(throwsError: true)
      let task = Task.retrying {
         try await service.operation()
      }
      do {
         _ = try await task.value
         XCTFail("Unexpected result returned")
      } catch let error as ServiceError {
         XCTAssertEqual(error, .thrown)
      } catch {
         XCTFail("Unexpected error thrown \(error)")
      }
   }

   func test_task_throwsCancelledError_ifCancelled() async {
      let service = Service(throwsError: true)
      let task = Task.retrying(retryDelay: 1.0) {
         try await service.operation()
      }
      DispatchQueue.main.asyncAfter(deadline: .now() + 0.5) {
         task.cancel()
      }

      do {
         _ = try await task.value
         XCTFail("Unexpected result returned")
      } catch {
         XCTAssertTrue(error is CancellationError)
      }
   }
}

private enum ServiceError: Error {
   case thrown
}

private class Service: @unchecked Sendable {
   private var isErrorThrown = false
   private let throwsError: Bool

   init(throwsError: Bool) {
      self.throwsError = throwsError
   }

   func operation() async throws -> Int {
      if throwsError {
         throw ServiceError.thrown
      }

      if isErrorThrown {
         return 42
      }

      isErrorThrown = true
      throw ServiceError.thrown
   }
}
